Workbook

Sheet Character
A1: Character Sheet — SRD 5.1
A2: Yellow cells: fill in (blue text). Grey cells: calculated — type in the Override column to replace a value. See the About sheet.
A3: IDENTITY | D3: CLASSES | H3: SKILLS
A4: Character name | D4: Class | E4: Subclass | F4: Level | H4: Skill | I4: Ability | J4: Proficiency | K4: Misc | L4: Total
A5: Display name | H5: Acrobatics | I5: DEX | J5: none | L5: =IF(INDEX($D$19:$D$24,MATCH(I5,$B$19:$B$24,0))="","",INDEX($D$19:$D$24,MATCH(I5,$B$19:$B$24,0))+IF(J5="expertise",2,IF(J5="proficient",1,0))*N($D$28)+N(K5))
A6: Player | H6: Animal Handling | I6: WIS | J6: none | L6: =IF(INDEX($D$19:$D$24,MATCH(I6,$B$19:$B$24,0))="","",INDEX($D$19:$D$24,MATCH(I6,$B$19:$B$24,0))+IF(J6="expertise",2,IF(J6="proficient",1,0))*N($D$28)+N(K6))
A7: Race | H7: Arcana | I7: INT | J7: none | L7: =IF(INDEX($D$19:$D$24,MATCH(I7,$B$19:$B$24,0))="","",INDEX($D$19:$D$24,MATCH(I7,$B$19:$B$24,0))+IF(J7="expertise",2,IF(J7="proficient",1,0))*N($D$28)+N(K7))
A8: Subrace | E8: Total level | F8: =SUM(F5:F7) -> 0 | H8: Athletics | I8: STR | J8: none | L8: =IF(INDEX($D$19:$D$24,MATCH(I8,$B$19:$B$24,0))="","",INDEX($D$19:$D$24,MATCH(I8,$B$19:$B$24,0))+IF(J8="expertise",2,IF(J8="proficient",1,0))*N($D$28)+N(K8))
A9: Alignment | D9: Multiclass: one row per class; the first row is the main class (hit dice, spellcasting). | H9: Deception | I9: CHA | J9: none | L9: =IF(INDEX($D$19:$D$24,MATCH(I9,$B$19:$B$24,0))="","",INDEX($D$19:$D$24,MATCH(I9,$B$19:$B$24,0))+IF(J9="expertise",2,IF(J9="proficient",1,0))*N($D$28)+N(K9))
A10: Faith | H10: History | I10: INT | J10: none | L10: =IF(INDEX($D$19:$D$24,MATCH(I10,$B$19:$B$24,0))="","",INDEX($D$19:$D$24,MATCH(I10,$B$19:$B$24,0))+IF(J10="expertise",2,IF(J10="proficient",1,0))*N($D$28)+N(K10))
A11: Age | H11: Insight | I11: WIS | J11: none | L11: =IF(INDEX($D$19:$D$24,MATCH(I11,$B$19:$B$24,0))="","",INDEX($D$19:$D$24,MATCH(I11,$B$19:$B$24,0))+IF(J11="expertise",2,IF(J11="proficient",1,0))*N($D$28)+N(K11))
A12: Gender | H12: Intimidation | I12: CHA | J12: none | L12: =IF(INDEX($D$19:$D$24,MATCH(I12,$B$19:$B$24,0))="","",INDEX($D$19:$D$24,MATCH(I12,$B$19:$B$24,0))+IF(J12="expertise",2,IF(J12="proficient",1,0))*N($D$28)+N(K12))
A13: Height | H13: Investigation | I13: INT | J13: none | L13: =IF(INDEX($D$19:$D$24,MATCH(I13,$B$19:$B$24,0))="","",INDEX($D$19:$D$24,MATCH(I13,$B$19:$B$24,0))+IF(J13="expertise",2,IF(J13="proficient",1,0))*N($D$28)+N(K13))
A14: Weight | H14: Medicine | I14: WIS | J14: none | L14: =IF(INDEX($D$19:$D$24,MATCH(I14,$B$19:$B$24,0))="","",INDEX($D$19:$D$24,MATCH(I14,$B$19:$B$24,0))+IF(J14="expertise",2,IF(J14="proficient",1,0))*N($D$28)+N(K14))
A15: Hometown | H15: Nature | I15: INT | J15: none | L15: =IF(INDEX($D$19:$D$24,MATCH(I15,$B$19:$B$24,0))="","",INDEX($D$19:$D$24,MATCH(I15,$B$19:$B$24,0))+IF(J15="expertise",2,IF(J15="proficient",1,0))*N($D$28)+N(K15))
H16: Perception | I16: WIS | J16: none | L16: =IF(INDEX($D$19:$D$24,MATCH(I16,$B$19:$B$24,0))="","",INDEX($D$19:$D$24,MATCH(I16,$B$19:$B$24,0))+IF(J16="expertise",2,IF(J16="proficient",1,0))*N($D$28)+N(K16))
A17: ABILITIES | H17: Performance | I17: CHA | J17: none | L17: =IF(INDEX($D$19:$D$24,MATCH(I17,$B$19:$B$24,0))="","",INDEX($D$19:$D$24,MATCH(I17,$B$19:$B$24,0))+IF(J17="expertise",2,IF(J17="proficient",1,0))*N($D$28)+N(K17))
A18: Ability | B18: Code | C18: Score | D18: Modifier | E18: Save prof. | F18: Save bonus | H18: Persuasion | I18: CHA | J18: none | L18: =IF(INDEX($D$19:$D$24,MATCH(I18,$B$19:$B$24,0))="","",INDEX($D$19:$D$24,MATCH(I18,$B$19:$B$24,0))+IF(J18="expertise",2,IF(J18="proficient",1,0))*N($D$28)+N(K18))
A19: Strength | B19: STR | D19: =IF(C19="","",INT((C19-10)/2)) | F19: =IF(D19="","",D19+IF(E19="Yes",$D$28,0)) | H19: Religion | I19: INT | J19: none | L19: =IF(INDEX($D$19:$D$24,MATCH(I19,$B$19:$B$24,0))="","",INDEX($D$19:$D$24,MATCH(I19,$B$19:$B$24,0))+IF(J19="expertise",2,IF(J19="proficient",1,0))*N($D$28)+N(K19))
A20: Dexterity | B20: DEX | D20: =IF(C20="","",INT((C20-10)/2)) | F20: =IF(D20="","",D20+IF(E20="Yes",$D$28,0)) | H20: Sleight of Hand | I20: DEX | J20: none | L20: =IF(INDEX($D$19:$D$24,MATCH(I20,$B$19:$B$24,0))="","",INDEX($D$19:$D$24,MATCH(I20,$B$19:$B$24,0))+IF(J20="expertise",2,IF(J20="proficient",1,0))*N($D$28)+N(K20))
A21: Constitution | B21: CON | D21: =IF(C21="","",INT((C21-10)/2)) | F21: =IF(D21="","",D21+IF(E21="Yes",$D$28,0)) | H21: Stealth | I21: DEX | J21: none | L21: =IF(INDEX($D$19:$D$24,MATCH(I21,$B$19:$B$24,0))="","",INDEX($D$19:$D$24,MATCH(I21,$B$19:$B$24,0))+IF(J21="expertise",2,IF(J21="proficient",1,0))*N($D$28)+N(K21))
A22: Intelligence | B22: INT | D22: =IF(C22="","",INT((C22-10)/2)) | F22: =IF(D22="","",D22+IF(E22="Yes",$D$28,0)) | H22: Survival | I22: WIS | J22: none | L22: =IF(INDEX($D$19:$D$24,MATCH(I22,$B$19:$B$24,0))="","",INDEX($D$19:$D$24,MATCH(I22,$B$19:$B$24,0))+IF(J22="expertise",2,IF(J22="proficient",1,0))*N($D$28)+N(K22))
A23: Wisdom | B23: WIS | D23: =IF(C23="","",INT((C23-10)/2)) | F23: =IF(D23="","",D23+IF(E23="Yes",$D$28,0))
A24: Charisma | B24: CHA | D24: =IF(C24="","",INT((C24-10)/2)) | F24: =IF(D24="","",D24+IF(E24="Yes",$D$28,0))
A26: CORE STATS
A27: Stat | B27: Calculated | C27: Override | D27: Value
A28: Proficiency bonus | B28: =IF($F$8>0,INT(($F$8-1)/4)+2,"") | D28: =IF(C28<>"",C28,B28)
A29: Initiative | B29: =IF($D$20="","",$D$20) | D29: =IF(C29<>"",C29,B29)
A30: Armor Class | B30: =IF(Inventory!$B$4="",10+N($D$20),Inventory!$B$4+IF(Inventory!$C$4="",N($D$20),MIN(N($D$20),Inventory!$C$4)))+N(Inventory!$B$7) -> 10 | D30: =IF(C30<>"",C30,B30) -> 10
A31: Speed (ft) | B31: =IFERROR(VLOOKUP($B$7,SRD!$J$2:$L$10,3,FALSE()),30) -> 30 | D31: =IF(C31<>"",C31,B31) -> 30
A32: Passive Perception | B32: =IF($L$16="","",10+$L$16) | D32: =IF(C32<>"",C32,B32)
A33: Size | B33: =IFERROR(VLOOKUP($B$7,SRD!$J$2:$L$10,2,FALSE()),"Medium") -> Medium | D33: =IF(C33<>"",C33,B33) -> Medium
A34: Armor Class uses the armor and shield on the Inventory sheet; type an Override for Unarmored Defense, Mage Armor, magic items…
A36: HIT POINTS | D36: HIT DICE
A37: HP max | D37: Die size | E37: =IFERROR("d"&VLOOKUP($D$5,SRD!$A$2:$E$13,2,FALSE()),"")
A38: HP current | D38: Max | E38: =IF($F$8>0,$F$8,"")
A39: Temporary HP | D39: Current
D40: Multiclass: the suite manages hit dice per die size (special resource).
A44: Template | B44: KnU-SRD-5.1 | C44: srd-1.0

Sheet Spells
A1: Spellcasting
B3: Calculated | C3: Override | D3: Value
A4: Spellcasting ability | B4: =IFERROR(IF(VLOOKUP(Character!$D$5,SRD!$A$2:$E$13,3,FALSE())="","",VLOOKUP(Character!$D$5,SRD!$A$2:$E$13,3,FALSE())),"") | D4: =IF(C4<>"",C4,B4)
A5: Spell save DC | B5: =IF($D$4="","",8+N(Character!$D$28)+N(INDEX(Character!$D$19:$D$24,MATCH($D$4,Character!$B$19:$B$24,0)))) | D5: =IF(C5<>"",C5,B5)
A6: Spell attack bonus | B6: =IF($D$4="","",N(Character!$D$28)+N(INDEX(Character!$D$19:$D$24,MATCH($D$4,Character!$B$19:$B$24,0)))) | D6: =IF(C6<>"",C6,B6)
A8: SPELL SLOTS | E8: SPECIAL RESOURCES
A9: Level | B9: Max | C9: Current | E9: Name | F9: Max | G9: Reset | H9: Die
A10: 1
A11: 2
A12: 3
A13: 4
A14: 5
A15: 6
A16: 7
A17: 8
A18: 9
E19: Rage, Ki points, Channel Divinity, Wild Shape… (become Resource Tracker resources).
A21: CANTRIPS | H21: Spells: pick from the SRD list or type a name (homebrew spells keep an empty level — type it in the Level cell).
A22: Spell | B22: Level | C22: School | D22: Conc. | E22: Range | F22: Ritual
B23: =IF(A23="","",IFERROR(VLOOKUP(A23,SRD!$AF$2:$AO$320,2,FALSE()),"")) | C23: =IF(A23="","",IFERROR(VLOOKUP(A23,SRD!$AF$2:$AO$320,3,FALSE()),"")) | D23: =IF(A23="","",IFERROR(VLOOKUP(A23,SRD!$AF$2:$AO$320,8,FALSE()),"")) | E23: =IF(A23="","",IFERROR(VLOOKUP(A23,SRD!$AF$2:$AO$320,5,FALSE()),"")) | F23: =IF(A23="","",IFERROR(VLOOKUP(A23,SRD!$AF$2:$AO$320,9,FALSE()),""))
B24: =IF(A24="","",IFERROR(VLOOKUP(A24,SRD!$AF$2:$AO$320,2,FALSE()),"")) | C24: =IF(A24="","",IFERROR(VLOOKUP(A24,SRD!$AF$2:$AO$320,3,FALSE()),"")) | D24: =IF(A24="","",IFERROR(VLOOKUP(A24,SRD!$AF$2:$AO$320,8,FALSE()),"")) | E24: =IF(A24="","",IFERROR(VLOOKUP(A24,SRD!$AF$2:$AO$320,5,FALSE()),"")) | F24: =IF(A24="","",IFERROR(VLOOKUP(A24,SRD!$AF$2:$AO$320,9,FALSE()),""))
B25: =IF(A25="","",IFERROR(VLOOKUP(A25,SRD!$AF$2:$AO$320,2,FALSE()),"")) | C25: =IF(A25="","",IFERROR(VLOOKUP(A25,SRD!$AF$2:$AO$320,3,FALSE()),"")) | D25: =IF(A25="","",IFERROR(VLOOKUP(A25,SRD!$AF$2:$AO$320,8,FALSE()),"")) | E25: =IF(A25="","",IFERROR(VLOOKUP(A25,SRD!$AF$2:$AO$320,5,FALSE()),"")) | F25: =IF(A25="","",IFERROR(VLOOKUP(A25,SRD!$AF$2:$AO$320,9,FALSE()),""))
B26: =IF(A26="","",IFERROR(VLOOKUP(A26,SRD!$AF$2:$AO$320,2,FALSE()),"")) | C26: =IF(A26="","",IFERROR(VLOOKUP(A26,SRD!$AF$2:$AO$320,3,FALSE()),"")) | D26: =IF(A26="","",IFERROR(VLOOKUP(A26,SRD!$AF$2:$AO$320,8,FALSE()),"")) | E26: =IF(A26="","",IFERROR(VLOOKUP(A26,SRD!$AF$2:$AO$320,5,FALSE()),"")) | F26: =IF(A26="","",IFERROR(VLOOKUP(A26,SRD!$AF$2:$AO$320,9,FALSE()),""))
B27: =IF(A27="","",IFERROR(VLOOKUP(A27,SRD!$AF$2:$AO$320,2,FALSE()),"")) | C27: =IF(A27="","",IFERROR(VLOOKUP(A27,SRD!$AF$2:$AO$320,3,FALSE()),"")) | D27: =IF(A27="","",IFERROR(VLOOKUP(A27,SRD!$AF$2:$AO$320,8,FALSE()),"")) | E27: =IF(A27="","",IFERROR(VLOOKUP(A27,SRD!$AF$2:$AO$320,5,FALSE()),"")) | F27: =IF(A27="","",IFERROR(VLOOKUP(A27,SRD!$AF$2:$AO$320,9,FALSE()),""))
B28: =IF(A28="","",IFERROR(VLOOKUP(A28,SRD!$AF$2:$AO$320,2,FALSE()),"")) | C28: =IF(A28="","",IFERROR(VLOOKUP(A28,SRD!$AF$2:$AO$320,3,FALSE()),"")) | D28: =IF(A28="","",IFERROR(VLOOKUP(A28,SRD!$AF$2:$AO$320,8,FALSE()),"")) | E28: =IF(A28="","",IFERROR(VLOOKUP(A28,SRD!$AF$2:$AO$320,5,FALSE()),"")) | F28: =IF(A28="","",IFERROR(VLOOKUP(A28,SRD!$AF$2:$AO$320,9,FALSE()),""))
B29: =IF(A29="","",IFERROR(VLOOKUP(A29,SRD!$AF$2:$AO$320,2,FALSE()),"")) | C29: =IF(A29="","",IFERROR(VLOOKUP(A29,SRD!$AF$2:$AO$320,3,FALSE()),"")) | D29: =IF(A29="","",IFERROR(VLOOKUP(A29,SRD!$AF$2:$AO$320,8,FALSE()),"")) | E29: =IF(A29="","",IFERROR(VLOOKUP(A29,SRD!$AF$2:$AO$320,5,FALSE()),"")) | F29: =IF(A29="","",IFERROR(VLOOKUP(A29,SRD!$AF$2:$AO$320,9,FALSE()),""))
B30: =IF(A30="","",IFERROR(VLOOKUP(A30,SRD!$AF$2:$AO$320,2,FALSE()),"")) | C30: =IF(A30="","",IFERROR(VLOOKUP(A30,SRD!$AF$2:$AO$320,3,FALSE()),"")) | D30: =IF(A30="","",IFERROR(VLOOKUP(A30,SRD!$AF$2:$AO$320,8,FALSE()),"")) | E30: =IF(A30="","",IFERROR(VLOOKUP(A30,SRD!$AF$2:$AO$320,5,FALSE()),"")) | F30: =IF(A30="","",IFERROR(VLOOKUP(A30,SRD!$AF$2:$AO$320,9,FALSE()),""))
B31: =IF(A31="","",IFERROR(VLOOKUP(A31,SRD!$AF$2:$AO$320,2,FALSE()),"")) | C31: =IF(A31="","",IFERROR(VLOOKUP(A31,SRD!$AF$2:$AO$320,3,FALSE()),"")) | D31: =IF(A31="","",IFERROR(VLOOKUP(A31,SRD!$AF$2:$AO$320,8,FALSE()),"")) | E31: =IF(A31="","",IFERROR(VLOOKUP(A31,SRD!$AF$2:$AO$320,5,FALSE()),"")) | F31: =IF(A31="","",IFERROR(VLOOKUP(A31,SRD!$AF$2:$AO$320,9,FALSE()),""))
B32: =IF(A32="","",IFERROR(VLOOKUP(A32,SRD!$AF$2:$AO$320,2,FALSE()),"")) | C32: =IF(A32="","",IFERROR(VLOOKUP(A32,SRD!$AF$2:$AO$320,3,FALSE()),"")) | D32: =IF(A32="","",IFERROR(VLOOKUP(A32,SRD!$AF$2:$AO$320,8,FALSE()),"")) | E32: =IF(A32="","",IFERROR(VLOOKUP(A32,SRD!$AF$2:$AO$320,5,FALSE()),"")) | F32: =IF(A32="","",IFERROR(VLOOKUP(A32,SRD!$AF$2:$AO$320,9,FALSE()),""))
A34: ALWAYS PREPARED
A35: Spell | B35: Level | C35: School | D35: Conc. | E35: Range | F35: Ritual
B36: =IF(A36="","",IFERROR(VLOOKUP(A36,SRD!$AF$2:$AO$320,2,FALSE()),"")) | C36: =IF(A36="","",IFERROR(VLOOKUP(A36,SRD!$AF$2:$AO$320,3,FALSE()),"")) | D36: =IF(A36="","",IFERROR(VLOOKUP(A36,SRD!$AF$2:$AO$320,8,FALSE()),"")) | E36: =IF(A36="","",IFERROR(VLOOKUP(A36,SRD!$AF$2:$AO$320,5,FALSE()),"")) | F36: =IF(A36="","",IFERROR(VLOOKUP(A36,SRD!$AF$2:$AO$320,9,FALSE()),""))
B37: =IF(A37="","",IFERROR(VLOOKUP(A37,SRD!$AF$2:$AO$320,2,FALSE()),"")) | C37: =IF(A37="","",IFERROR(VLOOKUP(A37,SRD!$AF$2:$AO$320,3,FALSE()),"")) | D37: =IF(A37="","",IFERROR(VLOOKUP(A37,SRD!$AF$2:$AO$320,8,FALSE()),"")) | E37: =IF(A37="","",IFERROR(VLOOKUP(A37,SRD!$AF$2:$AO$320,5,FALSE()),"")) | F37: =IF(A37="","",IFERROR(VLOOKUP(A37,SRD!$AF$2:$AO$320,9,FALSE()),""))
B38: =IF(A38="","",IFERROR(VLOOKUP(A38,SRD!$AF$2:$AO$320,2,FALSE()),"")) | C38: =IF(A38="","",IFERROR(VLOOKUP(A38,SRD!$AF$2:$AO$320,3,FALSE()),"")) | D38: =IF(A38="","",IFERROR(VLOOKUP(A38,SRD!$AF$2:$AO$320,8,FALSE()),"")) | E38: =IF(A38="","",IFERROR(VLOOKUP(A38,SRD!$AF$2:$AO$320,5,FALSE()),"")) | F38: =IF(A38="","",IFERROR(VLOOKUP(A38,SRD!$AF$2:$AO$320,9,FALSE()),""))
B39: =IF(A39="","",IFERROR(VLOOKUP(A39,SRD!$AF$2:$AO$320,2,FALSE()),"")) | C39: =IF(A39="","",IFERROR(VLOOKUP(A39,SRD!$AF$2:$AO$320,3,FALSE()),"")) | D39: =IF(A39="","",IFERROR(VLOOKUP(A39,SRD!$AF$2:$AO$320,8,FALSE()),"")) | E39: =IF(A39="","",IFERROR(VLOOKUP(A39,SRD!$AF$2:$AO$320,5,FALSE()),"")) | F39: =IF(A39="","",IFERROR(VLOOKUP(A39,SRD!$AF$2:$AO$320,9,FALSE()),""))
B40: =IF(A40="","",IFERROR(VLOOKUP(A40,SRD!$AF$2:$AO$320,2,FALSE()),"")) | C40: =IF(A40="","",IFERROR(VLOOKUP(A40,SRD!$AF$2:$AO$320,3,FALSE()),"")) | D40: =IF(A40="","",IFERROR(VLOOKUP(A40,SRD!$AF$2:$AO$320,8,FALSE()),"")) | E40: =IF(A40="","",IFERROR(VLOOKUP(A40,SRD!$AF$2:$AO$320,5,FALSE()),"")) | F40: =IF(A40="","",IFERROR(VLOOKUP(A40,SRD!$AF$2:$AO$320,9,FALSE()),""))
B41: =IF(A41="","",IFERROR(VLOOKUP(A41,SRD!$AF$2:$AO$320,2,FALSE()),"")) | C41: =IF(A41="","",IFERROR(VLOOKUP(A41,SRD!$AF$2:$AO$320,3,FALSE()),"")) | D41: =IF(A41="","",IFERROR(VLOOKUP(A41,SRD!$AF$2:$AO$320,8,FALSE()),"")) | E41: =IF(A41="","",IFERROR(VLOOKUP(A41,SRD!$AF$2:$AO$320,5,FALSE()),"")) | F41: =IF(A41="","",IFERROR(VLOOKUP(A41,SRD!$AF$2:$AO$320,9,FALSE()),""))
B42: =IF(A42="","",IFERROR(VLOOKUP(A42,SRD!$AF$2:$AO$320,2,FALSE()),"")) | C42: =IF(A42="","",IFERROR(VLOOKUP(A42,SRD!$AF$2:$AO$320,3,FALSE()),"")) | D42: =IF(A42="","",IFERROR(VLOOKUP(A42,SRD!$AF$2:$AO$320,8,FALSE()),"")) | E42: =IF(A42="","",IFERROR(VLOOKUP(A42,SRD!$AF$2:$AO$320,5,FALSE()),"")) | F42: =IF(A42="","",IFERROR(VLOOKUP(A42,SRD!$AF$2:$AO$320,9,FALSE()),""))
B43: =IF(A43="","",IFERROR(VLOOKUP(A43,SRD!$AF$2:$AO$320,2,FALSE()),"")) | C43: =IF(A43="","",IFERROR(VLOOKUP(A43,SRD!$AF$2:$AO$320,3,FALSE()),"")) | D43: =IF(A43="","",IFERROR(VLOOKUP(A43,SRD!$AF$2:$AO$320,8,FALSE()),"")) | E43: =IF(A43="","",IFERROR(VLOOKUP(A43,SRD!$AF$2:$AO$320,5,FALSE()),"")) | F43: =IF(A43="","",IFERROR(VLOOKUP(A43,SRD!$AF$2:$AO$320,9,FALSE()),""))
B44: =IF(A44="","",IFERROR(VLOOKUP(A44,SRD!$AF$2:$AO$320,2,FALSE()),"")) | C44: =IF(A44="","",IFERROR(VLOOKUP(A44,SRD!$AF$2:$AO$320,3,FALSE()),"")) | D44: =IF(A44="","",IFERROR(VLOOKUP(A44,SRD!$AF$2:$AO$320,8,FALSE()),"")) | E44: =IF(A44="","",IFERROR(VLOOKUP(A44,SRD!$AF$2:$AO$320,5,FALSE()),"")) | F44: =IF(A44="","",IFERROR(VLOOKUP(A44,SRD!$AF$2:$AO$320,9,FALSE()),""))
...

Sheet Features
A1: Features & Traits
A2: Write the features in your own words (descriptions are free text).
A4: CLASS FEATURES
A5: Name | B5: Level | C5: Description
A28: RACE FEATURES
A29: Name | B29: Level | C29: Description
A42: FEATS
A43: Name | B43: Level | C43: Description
A54: FIGHTING STYLES
A55: Name | C55: Description
A62: SPECIAL ABILITIES
A63: Name | B63: Level | C63: Description

Sheet Inventory
A1: Equipment & Inventory
A3: Armor | B3: AC base | C3: Dex cap | D3: Equipped | E3: Attuned
B4: =IF(OR($A$4="",$D$4="No"),"",IFERROR(VLOOKUP($A$4,SRD!$Q$2:$V$13,3,FALSE()),"")) | C4: =IF(OR($A$4="",$D$4="No"),"",IFERROR(VLOOKUP($A$4,SRD!$Q$2:$V$13,4,FALSE()),"")) | D4: Yes | E4: No | F4: Not in the list? Type the name and override the AC on the Character sheet.
A6: Shield | B6: AC bonus | D6: Equipped | E6: Attuned
A7: Shield | B7: =IF($D$7="Yes",2,0) -> 0 | D7: No | E7: No
A9: WEAPONS
A10: Weapon | B10: Proficient | C10: Magic + | D10: Attack | E10: Damage | F10: Damage type | G10: Properties | H10: Special properties
D11: =IF(A11="","",IF(IFERROR(VLOOKUP(A11,SRD!$X$2:$AD$38,6,FALSE()),"STR")="FIN",MAX(N(Character!$D$19),N(Character!$D$20)),IF(IFERROR(VLOOKUP(A11,SRD!$X$2:$AD$38,6,FALSE()),"STR")="DEX",N(Character!$D$20),N(Character!$D$19)))+IF(B11="Yes",N(Character!$D$28),0)+N(C11)) | E11: =IF(OR(A11="",IFERROR(VLOOKUP(A11,SRD!$X$2:$AD$38,3,FALSE()),"")=""),"",IFERROR(VLOOKUP(A11,SRD!$X$2:$AD$38,3,FALSE()),"")&IF((IF(IFERROR(VLOOKUP(A11,SRD!$X$2:$AD$38,6,FALSE()),"STR")="FIN",MAX(N(Character!$D$19),N(Character!$D$20)),IF(IFERROR(VLOOKUP(A11,SRD!$X$2:$AD$38,6,FALSE()),"STR")="DEX",N(Character!$D$20),N(Character!$D$19)))+N(C11))=0,"",IF((IF(IFERROR(VLOOKUP(A11,SRD!$X$2:$AD$38,6,FALSE()),"STR")="FIN",MAX(N(Character!$D$19),N(Character!$D$20)),IF(IFERROR(VLOOKUP(A11,SRD!$X$2:$AD$38,6,FALSE()),"STR")="DEX",N(Character!$D$20),N(Character!$D$19)))+N(C11))>0,"+"&(IF(IFERROR(VLOOKUP(A11,SRD!$X$2:$AD$38,6,FALSE()),"STR")="FIN",MAX(N(Character!$D$19),N(Character!$D$20)),IF(IFERROR(VLOOKUP(A11,SRD!$X$2:$AD$38,6,FALSE()),"STR")="DEX",N(Character!$D$20),N(Character!$D$19)))+N(C11)),""&(IF(IFERROR(VLOOKUP(A11,SRD!$X$2:$AD$38,6,FALSE()),"STR")="FIN",MAX(N(Character!$D$19),N(Character!$D$20)),IF(IFERROR(VLOOKUP(A11,SRD!$X$2:$AD$38,6,FALSE()),"STR")="DEX",N(Character!$D$20),N(Character!$D$19)))+N(C11))))) | F11: =IF(A11="","",IFERROR(VLOOKUP(A11,SRD!$X$2:$AD$38,4,FALSE()),"")) | G11: =IF(A11="","",IFERROR(VLOOKUP(A11,SRD!$X$2:$AD$38,5,FALSE()),""))
D12: =IF(A12="","",IF(IFERROR(VLOOKUP(A12,SRD!$X$2:$AD$38,6,FALSE()),"STR")="FIN",MAX(N(Character!$D$19),N(Character!$D$20)),IF(IFERROR(VLOOKUP(A12,SRD!$X$2:$AD$38,6,FALSE()),"STR")="DEX",N(Character!$D$20),N(Character!$D$19)))+IF(B12="Yes",N(Character!$D$28),0)+N(C12)) | E12: =IF(OR(A12="",IFERROR(VLOOKUP(A12,SRD!$X$2:$AD$38,3,FALSE()),"")=""),"",IFERROR(VLOOKUP(A12,SRD!$X$2:$AD$38,3,FALSE()),"")&IF((IF(IFERROR(VLOOKUP(A12,SRD!$X$2:$AD$38,6,FALSE()),"STR")="FIN",MAX(N(Character!$D$19),N(Character!$D$20)),IF(IFERROR(VLOOKUP(A12,SRD!$X$2:$AD$38,6,FALSE()),"STR")="DEX",N(Character!$D$20),N(Character!$D$19)))+N(C12))=0,"",IF((IF(IFERROR(VLOOKUP(A12,SRD!$X$2:$AD$38,6,FALSE()),"STR")="FIN",MAX(N(Character!$D$19),N(Character!$D$20)),IF(IFERROR(VLOOKUP(A12,SRD!$X$2:$AD$38,6,FALSE()),"STR")="DEX",N(Character!$D$20),N(Character!$D$19)))+N(C12))>0,"+"&(IF(IFERROR(VLOOKUP(A12,SRD!$X$2:$AD$38,6,FALSE()),"STR")="FIN",MAX(N(Character!$D$19),N(Character!$D$20)),IF(IFERROR(VLOOKUP(A12,SRD!$X$2:$AD$38,6,FALSE()),"STR")="DEX",N(Character!$D$20),N(Character!$D$19)))+N(C12)),""&(IF(IFERROR(VLOOKUP(A12,SRD!$X$2:$AD$38,6,FALSE()),"STR")="FIN",MAX(N(Character!$D$19),N(Character!$D$20)),IF(IFERROR(VLOOKUP(A12,SRD!$X$2:$AD$38,6,FALSE()),"STR")="DEX",N(Character!$D$20),N(Character!$D$19)))+N(C12))))) | F12: =IF(A12="","",IFERROR(VLOOKUP(A12,SRD!$X$2:$AD$38,4,FALSE()),"")) | G12: =IF(A12="","",IFERROR(VLOOKUP(A12,SRD!$X$2:$AD$38,5,FALSE()),""))
D13: =IF(A13="","",IF(IFERROR(VLOOKUP(A13,SRD!$X$2:$AD$38,6,FALSE()),"STR")="FIN",MAX(N(Character!$D$19),N(Character!$D$20)),IF(IFERROR(VLOOKUP(A13,SRD!$X$2:$AD$38,6,FALSE()),"STR")="DEX",N(Character!$D$20),N(Character!$D$19)))+IF(B13="Yes",N(Character!$D$28),0)+N(C13)) | E13: =IF(OR(A13="",IFERROR(VLOOKUP(A13,SRD!$X$2:$AD$38,3,FALSE()),"")=""),"",IFERROR(VLOOKUP(A13,SRD!$X$2:$AD$38,3,FALSE()),"")&IF((IF(IFERROR(VLOOKUP(A13,SRD!$X$2:$AD$38,6,FALSE()),"STR")="FIN",MAX(N(Character!$D$19),N(Character!$D$20)),IF(IFERROR(VLOOKUP(A13,SRD!$X$2:$AD$38,6,FALSE()),"STR")="DEX",N(Character!$D$20),N(Character!$D$19)))+N(C13))=0,"",IF((IF(IFERROR(VLOOKUP(A13,SRD!$X$2:$AD$38,6,FALSE()),"STR")="FIN",MAX(N(Character!$D$19),N(Character!$D$20)),IF(IFERROR(VLOOKUP(A13,SRD!$X$2:$AD$38,6,FALSE()),"STR")="DEX",N(Character!$D$20),N(Character!$D$19)))+N(C13))>0,"+"&(IF(IFERROR(VLOOKUP(A13,SRD!$X$2:$AD$38,6,FALSE()),"STR")="FIN",MAX(N(Character!$D$19),N(Character!$D$20)),IF(IFERROR(VLOOKUP(A13,SRD!$X$2:$AD$38,6,FALSE()),"STR")="DEX",N(Character!$D$20),N(Character!$D$19)))+N(C13)),""&(IF(IFERROR(VLOOKUP(A13,SRD!$X$2:$AD$38,6,FALSE()),"STR")="FIN",MAX(N(Character!$D$19),N(Character!$D$20)),IF(IFERROR(VLOOKUP(A13,SRD!$X$2:$AD$38,6,FALSE()),"STR")="DEX",N(Character!$D$20),N(Character!$D$19)))+N(C13))))) | F13: =IF(A13="","",IFERROR(VLOOKUP(A13,SRD!$X$2:$AD$38,4,FALSE()),"")) | G13: =IF(A13="","",IFERROR(VLOOKUP(A13,SRD!$X$2:$AD$38,5,FALSE()),""))
D14: =IF(A14="","",IF(IFERROR(VLOOKUP(A14,SRD!$X$2:$AD$38,6,FALSE()),"STR")="FIN",MAX(N(Character!$D$19),N(Character!$D$20)),IF(IFERROR(VLOOKUP(A14,SRD!$X$2:$AD$38,6,FALSE()),"STR")="DEX",N(Character!$D$20),N(Character!$D$19)))+IF(B14="Yes",N(Character!$D$28),0)+N(C14)) | E14: =IF(OR(A14="",IFERROR(VLOOKUP(A14,SRD!$X$2:$AD$38,3,FALSE()),"")=""),"",IFERROR(VLOOKUP(A14,SRD!$X$2:$AD$38,3,FALSE()),"")&IF((IF(IFERROR(VLOOKUP(A14,SRD!$X$2:$AD$38,6,FALSE()),"STR")="FIN",MAX(N(Character!$D$19),N(Character!$D$20)),IF(IFERROR(VLOOKUP(A14,SRD!$X$2:$AD$38,6,FALSE()),"STR")="DEX",N(Character!$D$20),N(Character!$D$19)))+N(C14))=0,"",IF((IF(IFERROR(VLOOKUP(A14,SRD!$X$2:$AD$38,6,FALSE()),"STR")="FIN",MAX(N(Character!$D$19),N(Character!$D$20)),IF(IFERROR(VLOOKUP(A14,SRD!$X$2:$AD$38,6,FALSE()),"STR")="DEX",N(Character!$D$20),N(Character!$D$19)))+N(C14))>0,"+"&(IF(IFERROR(VLOOKUP(A14,SRD!$X$2:$AD$38,6,FALSE()),"STR")="FIN",MAX(N(Character!$D$19),N(Character!$D$20)),IF(IFERROR(VLOOKUP(A14,SRD!$X$2:$AD$38,6,FALSE()),"STR")="DEX",N(Character!$D$20),N(Character!$D$19)))+N(C14)),""&(IF(IFERROR(VLOOKUP(A14,SRD!$X$2:$AD$38,6,FALSE()),"STR")="FIN",MAX(N(Character!$D$19),N(Character!$D$20)),IF(IFERROR(VLOOKUP(A14,SRD!$X$2:$AD$38,6,FALSE()),"STR")="DEX",N(Character!$D$20),N(Character!$D$19)))+N(C14))))) | F14: =IF(A14="","",IFERROR(VLOOKUP(A14,SRD!$X$2:$AD$38,4,FALSE()),"")) | G14: =IF(A14="","",IFERROR(VLOOKUP(A14,SRD!$X$2:$AD$38,5,FALSE()),""))
D15: =IF(A15="","",IF(IFERROR(VLOOKUP(A15,SRD!$X$2:$AD$38,6,FALSE()),"STR")="FIN",MAX(N(Character!$D$19),N(Character!$D$20)),IF(IFERROR(VLOOKUP(A15,SRD!$X$2:$AD$38,6,FALSE()),"STR")="DEX",N(Character!$D$20),N(Character!$D$19)))+IF(B15="Yes",N(Character!$D$28),0)+N(C15)) | E15: =IF(OR(A15="",IFERROR(VLOOKUP(A15,SRD!$X$2:$AD$38,3,FALSE()),"")=""),"",IFERROR(VLOOKUP(A15,SRD!$X$2:$AD$38,3,FALSE()),"")&IF((IF(IFERROR(VLOOKUP(A15,SRD!$X$2:$AD$38,6,FALSE()),"STR")="FIN",MAX(N(Character!$D$19),N(Character!$D$20)),IF(IFERROR(VLOOKUP(A15,SRD!$X$2:$AD$38,6,FALSE()),"STR")="DEX",N(Character!$D$20),N(Character!$D$19)))+N(C15))=0,"",IF((IF(IFERROR(VLOOKUP(A15,SRD!$X$2:$AD$38,6,FALSE()),"STR")="FIN",MAX(N(Character!$D$19),N(Character!$D$20)),IF(IFERROR(VLOOKUP(A15,SRD!$X$2:$AD$38,6,FALSE()),"STR")="DEX",N(Character!$D$20),N(Character!$D$19)))+N(C15))>0,"+"&(IF(IFERROR(VLOOKUP(A15,SRD!$X$2:$AD$38,6,FALSE()),"STR")="FIN",MAX(N(Character!$D$19),N(Character!$D$20)),IF(IFERROR(VLOOKUP(A15,SRD!$X$2:$AD$38,6,FALSE()),"STR")="DEX",N(Character!$D$20),N(Character!$D$19)))+N(C15)),""&(IF(IFERROR(VLOOKUP(A15,SRD!$X$2:$AD$38,6,FALSE()),"STR")="FIN",MAX(N(Character!$D$19),N(Character!$D$20)),IF(IFERROR(VLOOKUP(A15,SRD!$X$2:$AD$38,6,FALSE()),"STR")="DEX",N(Character!$D$20),N(Character!$D$19)))+N(C15))))) | F15: =IF(A15="","",IFERROR(VLOOKUP(A15,SRD!$X$2:$AD$38,4,FALSE()),"")) | G15: =IF(A15="","",IFERROR(VLOOKUP(A15,SRD!$X$2:$AD$38,5,FALSE()),""))
D16: =IF(A16="","",IF(IFERROR(VLOOKUP(A16,SRD!$X$2:$AD$38,6,FALSE()),"STR")="FIN",MAX(N(Character!$D$19),N(Character!$D$20)),IF(IFERROR(VLOOKUP(A16,SRD!$X$2:$AD$38,6,FALSE()),"STR")="DEX",N(Character!$D$20),N(Character!$D$19)))+IF(B16="Yes",N(Character!$D$28),0)+N(C16)) | E16: =IF(OR(A16="",IFERROR(VLOOKUP(A16,SRD!$X$2:$AD$38,3,FALSE()),"")=""),"",IFERROR(VLOOKUP(A16,SRD!$X$2:$AD$38,3,FALSE()),"")&IF((IF(IFERROR(VLOOKUP(A16,SRD!$X$2:$AD$38,6,FALSE()),"STR")="FIN",MAX(N(Character!$D$19),N(Character!$D$20)),IF(IFERROR(VLOOKUP(A16,SRD!$X$2:$AD$38,6,FALSE()),"STR")="DEX",N(Character!$D$20),N(Character!$D$19)))+N(C16))=0,"",IF((IF(IFERROR(VLOOKUP(A16,SRD!$X$2:$AD$38,6,FALSE()),"STR")="FIN",MAX(N(Character!$D$19),N(Character!$D$20)),IF(IFERROR(VLOOKUP(A16,SRD!$X$2:$AD$38,6,FALSE()),"STR")="DEX",N(Character!$D$20),N(Character!$D$19)))+N(C16))>0,"+"&(IF(IFERROR(VLOOKUP(A16,SRD!$X$2:$AD$38,6,FALSE()),"STR")="FIN",MAX(N(Character!$D$19),N(Character!$D$20)),IF(IFERROR(VLOOKUP(A16,SRD!$X$2:$AD$38,6,FALSE()),"STR")="DEX",N(Character!$D$20),N(Character!$D$19)))+N(C16)),""&(IF(IFERROR(VLOOKUP(A16,SRD!$X$2:$AD$38,6,FALSE()),"STR")="FIN",MAX(N(Character!$D$19),N(Character!$D$20)),IF(IFERROR(VLOOKUP(A16,SRD!$X$2:$AD$38,6,FALSE()),"STR")="DEX",N(Character!$D$20),N(Character!$D$19)))+N(C16))))) | F16: =IF(A16="","",IFERROR(VLOOKUP(A16,SRD!$X$2:$AD$38,4,FALSE()),"")) | G16: =IF(A16="","",IFERROR(VLOOKUP(A16,SRD!$X$2:$AD$38,5,FALSE()),""))
D17: =IF(A17="","",IF(IFERROR(VLOOKUP(A17,SRD!$X$2:$AD$38,6,FALSE()),"STR")="FIN",MAX(N(Character!$D$19),N(Character!$D$20)),IF(IFERROR(VLOOKUP(A17,SRD!$X$2:$AD$38,6,FALSE()),"STR")="DEX",N(Character!$D$20),N(Character!$D$19)))+IF(B17="Yes",N(Character!$D$28),0)+N(C17)) | E17: =IF(OR(A17="",IFERROR(VLOOKUP(A17,SRD!$X$2:$AD$38,3,FALSE()),"")=""),"",IFERROR(VLOOKUP(A17,SRD!$X$2:$AD$38,3,FALSE()),"")&IF((IF(IFERROR(VLOOKUP(A17,SRD!$X$2:$AD$38,6,FALSE()),"STR")="FIN",MAX(N(Character!$D$19),N(Character!$D$20)),IF(IFERROR(VLOOKUP(A17,SRD!$X$2:$AD$38,6,FALSE()),"STR")="DEX",N(Character!$D$20),N(Character!$D$19)))+N(C17))=0,"",IF((IF(IFERROR(VLOOKUP(A17,SRD!$X$2:$AD$38,6,FALSE()),"STR")="FIN",MAX(N(Character!$D$19),N(Character!$D$20)),IF(IFERROR(VLOOKUP(A17,SRD!$X$2:$AD$38,6,FALSE()),"STR")="DEX",N(Character!$D$20),N(Character!$D$19)))+N(C17))>0,"+"&(IF(IFERROR(VLOOKUP(A17,SRD!$X$2:$AD$38,6,FALSE()),"STR")="FIN",MAX(N(Character!$D$19),N(Character!$D$20)),IF(IFERROR(VLOOKUP(A17,SRD!$X$2:$AD$38,6,FALSE()),"STR")="DEX",N(Character!$D$20),N(Character!$D$19)))+N(C17)),""&(IF(IFERROR(VLOOKUP(A17,SRD!$X$2:$AD$38,6,FALSE()),"STR")="FIN",MAX(N(Character!$D$19),N(Character!$D$20)),IF(IFERROR(VLOOKUP(A17,SRD!$X$2:$AD$38,6,FALSE()),"STR")="DEX",N(Character!$D$20),N(Character!$D$19)))+N(C17))))) | F17: =IF(A17="","",IFERROR(VLOOKUP(A17,SRD!$X$2:$AD$38,4,FALSE()),"")) | G17: =IF(A17="","",IFERROR(VLOOKUP(A17,SRD!$X$2:$AD$38,5,FALSE()),""))
D18: =IF(A18="","",IF(IFERROR(VLOOKUP(A18,SRD!$X$2:$AD$38,6,FALSE()),"STR")="FIN",MAX(N(Character!$D$19),N(Character!$D$20)),IF(IFERROR(VLOOKUP(A18,SRD!$X$2:$AD$38,6,FALSE()),"STR")="DEX",N(Character!$D$20),N(Character!$D$19)))+IF(B18="Yes",N(Character!$D$28),0)+N(C18)) | E18: =IF(OR(A18="",IFERROR(VLOOKUP(A18,SRD!$X$2:$AD$38,3,FALSE()),"")=""),"",IFERROR(VLOOKUP(A18,SRD!$X$2:$AD$38,3,FALSE()),"")&IF((IF(IFERROR(VLOOKUP(A18,SRD!$X$2:$AD$38,6,FALSE()),"STR")="FIN",MAX(N(Character!$D$19),N(Character!$D$20)),IF(IFERROR(VLOOKUP(A18,SRD!$X$2:$AD$38,6,FALSE()),"STR")="DEX",N(Character!$D$20),N(Character!$D$19)))+N(C18))=0,"",IF((IF(IFERROR(VLOOKUP(A18,SRD!$X$2:$AD$38,6,FALSE()),"STR")="FIN",MAX(N(Character!$D$19),N(Character!$D$20)),IF(IFERROR(VLOOKUP(A18,SRD!$X$2:$AD$38,6,FALSE()),"STR")="DEX",N(Character!$D$20),N(Character!$D$19)))+N(C18))>0,"+"&(IF(IFERROR(VLOOKUP(A18,SRD!$X$2:$AD$38,6,FALSE()),"STR")="FIN",MAX(N(Character!$D$19),N(Character!$D$20)),IF(IFERROR(VLOOKUP(A18,SRD!$X$2:$AD$38,6,FALSE()),"STR")="DEX",N(Character!$D$20),N(Character!$D$19)))+N(C18)),""&(IF(IFERROR(VLOOKUP(A18,SRD!$X$2:$AD$38,6,FALSE()),"STR")="FIN",MAX(N(Character!$D$19),N(Character!$D$20)),IF(IFERROR(VLOOKUP(A18,SRD!$X$2:$AD$38,6,FALSE()),"STR")="DEX",N(Character!$D$20),N(Character!$D$19)))+N(C18))))) | F18: =IF(A18="","",IFERROR(VLOOKUP(A18,SRD!$X$2:$AD$38,4,FALSE()),"")) | G18: =IF(A18="","",IFERROR(VLOOKUP(A18,SRD!$X$2:$AD$38,5,FALSE()),""))
D19: =IF(A19="","",IF(IFERROR(VLOOKUP(A19,SRD!$X$2:$AD$38,6,FALSE()),"STR")="FIN",MAX(N(Character!$D$19),N(Character!$D$20)),IF(IFERROR(VLOOKUP(A19,SRD!$X$2:$AD$38,6,FALSE()),"STR")="DEX",N(Character!$D$20),N(Character!$D$19)))+IF(B19="Yes",N(Character!$D$28),0)+N(C19)) | E19: =IF(OR(A19="",IFERROR(VLOOKUP(A19,SRD!$X$2:$AD$38,3,FALSE()),"")=""),"",IFERROR(VLOOKUP(A19,SRD!$X$2:$AD$38,3,FALSE()),"")&IF((IF(IFERROR(VLOOKUP(A19,SRD!$X$2:$AD$38,6,FALSE()),"STR")="FIN",MAX(N(Character!$D$19),N(Character!$D$20)),IF(IFERROR(VLOOKUP(A19,SRD!$X$2:$AD$38,6,FALSE()),"STR")="DEX",N(Character!$D$20),N(Character!$D$19)))+N(C19))=0,"",IF((IF(IFERROR(VLOOKUP(A19,SRD!$X$2:$AD$38,6,FALSE()),"STR")="FIN",MAX(N(Character!$D$19),N(Character!$D$20)),IF(IFERROR(VLOOKUP(A19,SRD!$X$2:$AD$38,6,FALSE()),"STR")="DEX",N(Character!$D$20),N(Character!$D$19)))+N(C19))>0,"+"&(IF(IFERROR(VLOOKUP(A19,SRD!$X$2:$AD$38,6,FALSE()),"STR")="FIN",MAX(N(Character!$D$19),N(Character!$D$20)),IF(IFERROR(VLOOKUP(A19,SRD!$X$2:$AD$38,6,FALSE()),"STR")="DEX",N(Character!$D$20),N(Character!$D$19)))+N(C19)),""&(IF(IFERROR(VLOOKUP(A19,SRD!$X$2:$AD$38,6,FALSE()),"STR")="FIN",MAX(N(Character!$D$19),N(Character!$D$20)),IF(IFERROR(VLOOKUP(A19,SRD!$X$2:$AD$38,6,FALSE()),"STR")="DEX",N(Character!$D$20),N(Character!$D$19)))+N(C19))))) | F19: =IF(A19="","",IFERROR(VLOOKUP(A19,SRD!$X$2:$AD$38,4,FALSE()),"")) | G19: =IF(A19="","",IFERROR(VLOOKUP(A19,SRD!$X$2:$AD$38,5,FALSE()),""))
D20: =IF(A20="","",IF(IFERROR(VLOOKUP(A20,SRD!$X$2:$AD$38,6,FALSE()),"STR")="FIN",MAX(N(Character!$D$19),N(Character!$D$20)),IF(IFERROR(VLOOKUP(A20,SRD!$X$2:$AD$38,6,FALSE()),"STR")="DEX",N(Character!$D$20),N(Character!$D$19)))+IF(B20="Yes",N(Character!$D$28),0)+N(C20)) | E20: =IF(OR(A20="",IFERROR(VLOOKUP(A20,SRD!$X$2:$AD$38,3,FALSE()),"")=""),"",IFERROR(VLOOKUP(A20,SRD!$X$2:$AD$38,3,FALSE()),"")&IF((IF(IFERROR(VLOOKUP(A20,SRD!$X$2:$AD$38,6,FALSE()),"STR")="FIN",MAX(N(Character!$D$19),N(Character!$D$20)),IF(IFERROR(VLOOKUP(A20,SRD!$X$2:$AD$38,6,FALSE()),"STR")="DEX",N(Character!$D$20),N(Character!$D$19)))+N(C20))=0,"",IF((IF(IFERROR(VLOOKUP(A20,SRD!$X$2:$AD$38,6,FALSE()),"STR")="FIN",MAX(N(Character!$D$19),N(Character!$D$20)),IF(IFERROR(VLOOKUP(A20,SRD!$X$2:$AD$38,6,FALSE()),"STR")="DEX",N(Character!$D$20),N(Character!$D$19)))+N(C20))>0,"+"&(IF(IFERROR(VLOOKUP(A20,SRD!$X$2:$AD$38,6,FALSE()),"STR")="FIN",MAX(N(Character!$D$19),N(Character!$D$20)),IF(IFERROR(VLOOKUP(A20,SRD!$X$2:$AD$38,6,FALSE()),"STR")="DEX",N(Character!$D$20),N(Character!$D$19)))+N(C20)),""&(IF(IFERROR(VLOOKUP(A20,SRD!$X$2:$AD$38,6,FALSE()),"STR")="FIN",MAX(N(Character!$D$19),N(Character!$D$20)),IF(IFERROR(VLOOKUP(A20,SRD!$X$2:$AD$38,6,FALSE()),"STR")="DEX",N(Character!$D$20),N(Character!$D$19)))+N(C20))))) | F20: =IF(A20="","",IFERROR(VLOOKUP(A20,SRD!$X$2:$AD$38,4,FALSE()),"")) | G20: =IF(A20="","",IFERROR(VLOOKUP(A20,SRD!$X$2:$AD$38,5,FALSE()),""))
A21: Custom / magic weapons: type the name, then type Attack, Damage, Damage type over the grey cells.
A23: CURRENCY
A24: cp | B24: sp | C24: ep | D24: gp | E24: pp
A27: ITEMS
A28: Item | B28: Qty | C28: Weight (each) | D28: Location | E28: Description | G28: Total weight (lb) | H28: =SUMPRODUCT(B29:B68,C29:C68) -> 0
G29: Carrying capacity (lb) | H29: =IF(Character!$C$19="","",Character!$C$19*15)
A71: MAGIC ITEMS
A72: Item | B72: Description

Sheet Background
A1: Background, Proficiencies & Defenses
A2: Lists (languages, tools, defenses): separate entries with commas or semicolons.
A4: Background
A5: Background feature
A6: Personality traits
A7: Appearance / description
A8: Story
A9: Languages
A10: Tool proficiencies
A11: Resistances
A12: Immunities
A13: Advantages
A14: Disadvantages

Sheet About
A1: Character Sheet — SRD 5.1 (KnU Full Suite)
A3: HOW TO FILL
A4: • Yellow cells (blue text) are yours to fill. Grey cells are calculated.
A5: • Lists: SRD races, classes, subclasses, armor, weapons and spells come from the SRD 5.1. You can also type your own names.
A6: • Character → Core stats: type a value in the Override column to replace a calculated one (e.g. Unarmored Defense AC).
A7: • One row per entry in every table (classes, skills, spells, weapons, items, features). Empty rows are ignored.
A9: IMPORT IN THE SUITE
A10: • Save the file as .xlsx (Excel, LibreOffice or Google Sheets → Download as .xlsx), then drop it on the Character Cards panel.
A11: • The suite reads the cells through the named ranges listed on the Keys sheet ("cc.…"). Moving cells is fine as long as the names follow them; do not rename or delete them.
A12: • Spell, feature and item details in the suite come from your enabled 5etools libraries.
A14: LICENSE / ATTRIBUTION
A15: This work includes material taken from the System Reference Document 5.1 ("SRD 5.1") by Wizards of the Coast LLC and available at https://dnd.wizards.com/resources/systems-reference-document. The SRD 5.1 is licensed under the Creative Commons Attribution 4.0 International License available at https://creativecommons.org/licenses/by/4.0/legalcode.
... A17: Template: KnU-SRD-5.1 · layout srd-1.0

Sheet Keys
A1: Conversion keys (named ranges read by the suite)
A3: Key (defined name) | B3: Cells | C3: JSON field | D3: Type | E3: Notes
A4: cc.identity.character_name | B4: Character!B4 | C4: identity.character_name | D4: text
A5: cc.identity.display_name | B5: Character!B5 | C5: identity.display_name | D5: text
A6: cc.identity.player | B6: Character!B6 | C6: identity.player | D6: text
A7: cc.identity.race.name | B7: Character!B7 | C7: identity.race.name | D7: text
A8: cc.identity.race.subrace | B8: Character!B8 | C8: identity.race.subrace | D8: text
A9: cc.identity.alignment | B9: Character!B9 | C9: identity.alignment | D9: text
A10: cc.identity.faith | B10: Character!B10 | C10: identity.faith | D10: text
A11: cc.identity.age | B11: Character!B11 | C11: identity.age | D11: number
A12: cc.identity.gender | B12: Character!B12 | C12: identity.gender | D12: text
A13: cc.identity.height | B13: Character!B13 | C13: identity.height | D13: text
A14: cc.identity.weight | B14: Character!B14 | C14: identity.weight | D14: text
A15: cc.identity.hometown | B15: Character!B15 | C15: identity.hometown | D15: text
A16: cc.classes.name | B16: Character!D5:D7 | C16: classes[].name | D16: list | E16: First row = main class.
A17: cc.classes.subclass | B17: Character!E5:E7 | C17: classes[].subclass | D17: list
A18: cc.classes.level | B18: Character!F5:F7 | C18: classes[].level | D18: list (number)
A19: cc.total_level | B19: Character!F8 | C19: total_level | D19: number
A20: cc.abilities.str.total | B20: Character!C19 | C20: abilities.str.total | D20: number
A21: cc.abilities.str.modifier | B21: Character!D19 | C21: abilities.str.modifier | D21: number
A22: cc.abilities.str.save.proficient | B22: Character!E19 | C22: abilities.str.save.proficient | D22: Yes/No
A23: cc.abilities.str.save.bonus | B23: Character!F19 | C23: abilities.str.save.bonus | D23: number
A24: cc.abilities.dex.total | B24: Character!C20 | C24: abilities.dex.total | D24: number
A25: cc.abilities.dex.modifier | B25: Character!D20 | C25: abilities.dex.modifier | D25: number
A26: cc.abilities.dex.save.proficient | B26: Character!E20 | C26: abilities.dex.save.proficient | D26: Yes/No
A27: cc.abilities.dex.save.bonus | B27: Character!F20 | C27: abilities.dex.save.bonus | D27: number
A28: cc.abilities.con.total | B28: Character!C21 | C28: abilities.con.total | D28: number
... A54: cc.core_stats.hit_dice.max | B54: Character!E38 | C54: core_stats.hit_dice.max | D54: number
A55: cc.core_stats.hit_dice.current | B55: Character!E39 | C55: core_stats.hit_dice.current | D55: number | E55: Empty = all available.
A56: cc.skills.name | B56: Character!H5:H22 | C56: skills[].name | D56: list
A57: cc.skills.ability | B57: Character!I5:I22 | C57: skills[].ability | D57: list (STR…CHA → str…cha)
A58: cc.skills.proficiency | B58: Character!J5:J22 | C58: skills[].proficiency | D58: list: none / proficient / expertise
A59: cc.skills.misc_bonus | B59: Character!K5:K22 | C59: skills[].misc_bonus | D59: list (number)
A60: cc.skills.total | B60: Character!L5:L22 | C60: skills[].total | D60: list (number)
A61: cc.meta.template | B61: Character!B44 | C61: meta.template_name | D61: text | E61: Do not edit.
A62: cc.meta.layout_version | B62: Character!C44 | C62: meta.layout_version | D62: text | E62: Do not edit.
A63: cc.spellcasting.spellcasting_ability | B63: Spells!D4 | C63: spellcasting.spellcasting_ability (+ core_stats.dc_ability) | D63: STR…CHA → str…cha
A64: cc.spellcasting.save_dc | B64: Spells!D5 | C64: spellcasting.save_dc (+ core_stats.dc) | D64: number
A65: cc.spellcasting.attack_bonus | B65: Spells!D6 | C65: spellcasting.attack_bonus | D65: number → "+N"
A66: cc.spellcasting.spell_slots.max | B66: Spells!B10:B18 | C66: spellcasting.spell_slots.{level}.max | D66: list (number), row = slot level 1–9
...

Sheet SRD
A1: Class | B1: Hit die | C1: Spell ability | D1: Save 1 | E1: Save 2 | G1: Subclass | H1: Class | J1: Race | K1: Size | L1: Speed | N1: Subrace | O1: Race | Q1: Armor | R1: Category | S1: AC base | T1: Dex cap | U1: Stealth disadv. | V1: Weight | X1: Weapon | Y1: Category | Z1: Damage | AA1: Damage type | AB1: Properties | AC1: Attack ability | AD1: Weight | AF1: Spell | AG1: Level | AH1: School | AI1: Casting time | AJ1: Range | AK1: Components | AL1: Duration | AM1: Concentration | AN1: Ritual | AO1: Classes | AQ1: Skill | AR1: Ability | AT1: Alignment | AU1: Yes/No | AV1: Proficiency | AW1: Reset | AX1: Language | AY1: Damage type | AZ1: Condition | BA1: Ability | BB1: Size | BC1: Background | BD1: Feat | BE1: Location | BF1: Hit die
A2: Barbarian | B2: 12 | D2: STR | E2: CON | G2: Path of the Berserker | H2: Barbarian | J2: Dwarf | K2: Medium | L2: 25 | N2: Hill Dwarf | O2: Dwarf | Q2: Padded Armor | R2: Light | S2: 11 | U2: Yes | V2: 8 | X2: Club | Y2: Simple Melee | Z2: 1d4 | AA2: Bludgeoning | AB2: Light | AC2: STR | AD2: 2 | AF2: Acid Splash | AG2: 0 | AH2: Conjuration | AI2: 1 action | AJ2: 60 feet | AK2: V, S | AL2: Instantaneous | AM2: No | AN2: No | AO2: Sorcerer, Wizard | AQ2: Acrobatics | AR2: DEX | AT2: Lawful Good | AU2: Yes | AV2: none | AW2: SR | AX2: Common | AY2: Acid | AZ2: Blinded | BA2: STR | BB2: Tiny | BC2: Acolyte | BD2: Grappler | BE2: Equipped | BF2: d6
A3: Bard | B3: 8 | C3: CHA | D3: DEX | E3: CHA | G3: College of Lore | H3: Bard | J3: Elf | K3: Medium | L3: 30 | N3: High Elf | O3: Elf | Q3: Leather Armor | R3: Light | S3: 11 | U3: No | V3: 10 | X3: Dagger | Y3: Simple Melee | Z3: 1d4 | AA3: Piercing | AB3: Finesse, Light, Thrown (20/60) | AC3: FIN | AD3: 1 | AF3: Chill Touch | AG3: 0 | AH3: Necromancy | AI3: 1 action | AJ3: 120 feet | AK3: V, S | AL3: 1 round | AM3: No | AN3: No | AO3: Sorcerer, Warlock, Wizard | AQ3: Animal Handling | AR3: WIS | AT3: Neutral Good | AU3: No | AV3: proficient | AW3: LR | AX3: Dwarvish | AY3: Bludgeoning | AZ3: Charmed | BA3: DEX | BB3: Small | BE3: Backpack | BF3: d8
A4: Cleric | B4: 8 | C4: WIS | D4: WIS | E4: CHA | G4: Life Domain | H4: Cleric | J4: Halfling | K4: Small | L4: 25 | N4: Lightfoot Halfling | O4: Halfling | Q4: Studded Leather Armor | R4: Light | S4: 12 | U4: No | V4: 13 | X4: Greatclub | Y4: Simple Melee | Z4: 1d8 | AA4: Bludgeoning | AB4: Two-Handed | AC4: STR | AD4: 10 | AF4: Dancing Lights | AG4: 0 | AH4: Evocation | AI4: 1 action | AJ4: 120 feet | AK4: V, S, M | AL4: Up to 1 minute | AM4: Yes | AN4: No | AO4: Bard, Sorcerer, Wizard | AQ4: Arcana | AR4: INT | AT4: Chaotic Good | AV4: expertise | AX4: Elvish | AY4: Cold | AZ4: Deafened | BA4: CON | BB4: Medium | BE4: Belt pouch | BF4: d10
A5: Druid | B5: 8 | C5: WIS | D5: INT | E5: WIS | G5: Circle of the Land | H5: Druid | J5: Human | K5: Medium | L5: 30 | N5: Rock Gnome | O5: Gnome | Q5: Hide Armor | R5: Medium | S5: 12 | T5: 2 | U5: No | V5: 12 | X5: Handaxe | Y5: Simple Melee | Z5: 1d6 | AA5: Slashing | AB5: Light, Thrown (20/60) | AC5: STR | AD5: 2 | AF5: Druidcraft | AG5: 0 | AH5: Transmutation | AI5: 1 action | AJ5: 30 feet | AK5: V, S | AL5: Instantaneous | AM5: No | AN5: No | AO5: Druid | AQ5: Athletics | AR5: STR | AT5: Lawful Neutral | AX5: Giant | AY5: Fire | AZ5: Frightened | BA5: INT | BB5: Large | BE5: Storage | BF5: d12
A6: Fighter | B6: 10 | D6: STR | E6: CON | G6: Champion | H6: Fighter | J6: Dragonborn | K6: Medium | L6: 30 | Q6: Chain Shirt | R6: Medium | S6: 13 | T6: 2 | U6: No | V6: 20 | X6: Javelin | Y6: Simple Melee | Z6: 1d6 | AA6: Piercing | AB6: Thrown (30/120) | AC6: STR | AD6: 2 | AF6: Eldritch Blast | AG6: 0 | AH6: Evocation | AI6: 1 action | AJ6: 120 feet | AK6: V, S | AL6: Instantaneous | AM6: No | AN6: No | AO6: Warlock | AQ6: Deception | AR6: CHA | AT6: True Neutral | AX6: Gnomish | AY6: Force | AZ6: Grappled | BA6: WIS | BB6: Huge | BE6: Other
A7: Monk | B7: 8 | D7: STR | E7: DEX | G7: Way of the Open Hand | H7: Monk | J7: Gnome | K7: Small | L7: 25 | Q7: Scale Mail | R7: Medium | S7: 14 | T7: 2 | U7: Yes | V7: 45 | X7: Light hammer | Y7: Simple Melee | Z7: 1d4 | AA7: Bludgeoning | AB7: Light, Thrown (20/60) | AC7: STR | AD7: 2 | AF7: Fire Bolt | AG7: 0 | AH7: Evocation | AI7: 1 action | AJ7: 120 feet | AK7: V, S | AL7: Instantaneous | AM7: No | AN7: No | AO7: Sorcerer, Wizard | AQ7: History | AR7: INT | AT7: Chaotic Neutral | AX7: Goblin | AY7: Lightning | AZ7: Incapacitated | BA7: CHA | BB7: Gargantuan
A8: Paladin | B8: 10 | C8: CHA | D8: WIS | E8: CHA | G8: Oath of Devotion | H8: Paladin | J8: Half-Elf | K8: Medium | L8: 30 | Q8: Breastplate | R8: Medium | S8: 14 | T8: 2 | U8: No | V8: 20 | X8: Mace | Y8: Simple Melee | Z8: 1d6 | AA8: Bludgeoning | AC8: STR | AD8: 4 | AF8: Guidance | AG8: 0 | AH8: Divination | AI8: 1 action | AJ8: Touch | AK8: V, S | AL8: Up to 1 minute | AM8: Yes | AN8: No | AO8: Cleric, Druid | AQ8: Insight | AR8: WIS | AT8: Lawful Evil | AX8: Halfling | AY8: Necrotic | AZ8: Invisible
A9: Ranger | B9: 10 | C9: WIS | D9: STR | E9: DEX | G9: Hunter | H9: Ranger | J9: Half-Orc | K9: Medium | L9: 30 | Q9: Half Plate Armor | R9: Medium | S9: 15 | T9: 2 | U9: Yes | V9: 40 | X9: Quarterstaff | Y9: Simple Melee | Z9: 1d6 | AA9: Bludgeoning | AB9: Versatile (1d8) | AC9: STR | AD9: 4 | AF9: Light | AG9: 0 | AH9: Evocation | AI9: 1 action | AJ9: Touch | AK9: V, M | AL9: 1 hour | AM9: No | AN9: No | AO9: Bard, Cleric, Sorcerer, Wizard | AQ9: Intimidation | AR9: CHA | AT9: Neutral Evil | AX9: Orc | AY9: Piercing | AZ9: Paralyzed
A10: Rogue | B10: 8 | D10: DEX | E10: INT | G10: Thief | H10: Rogue | J10: Tiefling | K10: Medium | L10: 30 | Q10: Ring Mail | R10: Heavy | S10: 14 | T10: 0 | U10: Yes | V10: 40 | X10: Sickle | Y10: Simple Melee | Z10: 1d4 | AA10: Slashing | AB10: Light | AC10: STR | AD10: 2 | AF10: Mage Hand | AG10: 0 | AH10: Conjuration | AI10: 1 action | AJ10: 30 feet | AK10: V, S | AL10: 1 minute | AM10: No | AN10: No | AO10: Bard, Sorcerer, Warlock, Wizard | AQ10: Investigation | AR10: INT | AT10: Chaotic Evil | AX10: Abyssal | AY10: Poison | AZ10: Petrified
A11: Sorcerer | B11: 6 | C11: CHA | D11: CON | E11: CHA | G11: Draconic Bloodline | H11: Sorcerer | Q11: Chain Mail | R11: Heavy | S11: 16 | T11: 0 | U11: Yes | V11: 55 | X11: Spear | Y11: Simple Melee | Z11: 1d6 | AA11: Piercing | AB11: Thrown (20/60), Versatile (1d8) | AC11: STR | AD11: 3 | AF11: Mending | AG11: 0 | AH11: Transmutation | AI11: 1 minute | AJ11: Touch | AK11: V, S, M | AL11: Instantaneous | AM11: No | AN11: No | AO11: Cleric, Bard, Druid, Sorcerer, Wizard | AQ11: Medicine | AR11: WIS | AX11: Celestial | AY11: Psychic | AZ11: Poisoned
A12: Warlock | B12: 8 | C12: CHA | D12: WIS | E12: CHA | G12: The Fiend | H12: Warlock | Q12: Splint Armor | R12: Heavy | S12: 17 | T12: 0 | U12: Yes | V12: 60 | X12: Crossbow, light | Y12: Simple Ranged | Z12: 1d8 | AA12: Piercing | AB12: Ammunition (80/320), Loading, Two-Handed | AC12: DEX | AD12: 5 | AF12: Message | AG12: 0 | AH12: Transmutation | AI12: 1 action | AJ12: 120 feet | AK12: V, S, M | AL12: 1 round | AM12: No | AN12: No | AO12: Bard, Sorcerer, Wizard | AQ12: Nature | AR12: INT | AX12: Draconic | AY12: Radiant | AZ12: Prone
A13: Wizard | B13: 6 | C13: INT | D13: INT | E13: WIS | G13: School of Evocation | H13: Wizard | Q13: Plate Armor | R13: Heavy | S13: 18 | T13: 0 | U13: Yes | V13: 65 | X13: Dart | Y13: Simple Ranged | Z13: 1d4 | AA13: Piercing | AB13: Finesse, Thrown (20/60) | AC13: FIN | AD13: 0.25 | AF13: Minor Illusion | AG13: 0 | AH13: Illusion | AI13: 1 action | AJ13: 30 feet | AK13: S, M | AL13: 1 minute | AM13: No | AN13: No | AO13: Bard, Sorcerer, Warlock, Wizard | AQ13: Perception | AR13: WIS | AX13: Deep Speech | AY13: Slashing | AZ13: Restrained
X14: Shortbow | Y14: Simple Ranged | Z14: 1d6 | AA14: Piercing | AB14: Ammunition (80/320), Two-Handed | AC14: DEX | AD14: 2 | AF14: Poison Spray | AG14: 0 | AH14: Conjuration | AI14: 1 action | AJ14: 10 feet | AK14: V, S | AL14: Instantaneous | AM14: No | AN14: No | AO14: Sorcerer, Warlock, Wizard, Druid | AQ14: Performance | AR14: CHA | AX14: Infernal | AY14: Thunder | AZ14: Stunned
X15: Sling | Y15: Simple Ranged | Z15: 1d4 | AA15: Bludgeoning | AB15: Ammunition (30/120) | AC15: DEX | AD15: 0 | AF15: Prestidigitation | AG15: 0 | AH15: Transmutation | AI15: 1 action | AJ15: 10 feet | AK15: V, S | AL15: 1 hour | AM15: No | AN15: No | AO15: Bard, Sorcerer, Warlock, Wizard | AQ15: Persuasion | AR15: CHA | AX15: Primordial | AZ15: Unconscious
X16: Battleaxe | Y16: Martial Melee | Z16: 1d8 | AA16: Slashing | AB16: Versatile (1d10) | AC16: STR | AD16: 4 | AF16: Produce Flame | AG16: 0 | AH16: Conjuration | AI16: 1 action | AJ16: Self | AK16: V, S | AL16: 10 minutes | AM16: No | AN16: No | AO16: Druid | AQ16: Religion | AR16: INT | AX16: Sylvan | AZ16: Exhaustion
X17: Flail | Y17: Martial Melee | Z17: 1d8 | AA17: Bludgeoning | AC17: STR | AD17: 2 | AF17: Ray of Frost | AG17: 0 | AH17: Evocation | AI17: 1 action | AJ17: 60 feet | AK17: V, S | AL17: Instantaneous | AM17: No | AN17: No | AO17: Sorcerer, Wizard | AQ17: Sleight of Hand | AR17: DEX | AX17: Undercommon
X18: Glaive | Y18: Martial Melee | Z18: 1d10 | AA18: Slashing | AB18: Heavy, Reach, Two-Handed | AC18: STR | AD18: 6 | AF18: Resistance | AG18: 0 | AH18: Abjuration | AI18: 1 action | AJ18: Touch | AK18: V, S, M | AL18: Up to 1 minute | AM18: Yes | AN18: No | AO18: Cleric, Druid | AQ18: Stealth | AR18: DEX
X19: Greataxe | Y19: Martial Melee | Z19: 1d12 | AA19: Slashing | AB19: Heavy, Two-Handed | AC19: STR | AD19: 7 | AF19: Sacred Flame | AG19: 0 | AH19: Evocation | AI19: 1 action | AJ19: 60 feet | AK19: V, S | AL19: Instantaneous | AM19: No | AN19: No | AO19: Cleric | AQ19: Survival | AR19: WIS
X20: Greatsword | Y20: Martial Melee | Z20: 2d6 | AA20: Slashing | AB20: Heavy, Two-Handed | AC20: STR | AD20: 6 | AF20: Shillelagh | AG20: 0 | AH20: Transmutation | AI20: 1 bonus action | AJ20: Touch | AK20: V, S, M | AL20: 1 minute | AM20: No | AN20: No | AO20: Druid
X21: Halberd | Y21: Martial Melee | Z21: 1d10 | AA21: Slashing | AB21: Heavy, Reach, Two-Handed | AC21: STR | AD21: 6 | AF21: Shocking Grasp | AG21: 0 | AH21: Evocation | AI21: 1 action | AJ21: Touch | AK21: V, S | AL21: Instantaneous | AM21: No | AN21: No | AO21: Sorcerer, Wizard
X22: Lance | Y22: Martial Melee | Z22: 1d12 | AA22: Piercing | AB22: Reach, Special | AC22: STR | AD22: 6 | AF22: Spare the Dying | AG22: 0 | AH22: Necromancy | AI22: 1 action | AJ22: Touch | AK22: V, S | AL22: Instantaneous | AM22: No | AN22: No | AO22: Cleric
X23: Longsword | Y23: Martial Melee | Z23: 1d8 | AA23: Slashing | AB23: Versatile (1d10) | AC23: STR | AD23: 3 | AF23: Thaumaturgy | AG23: 0 | AH23: Transmutation | AI23: 1 action | AJ23: 30 feet | AK23: V | AL23: 1 minute | AM23: No | AN23: No | AO23: Cleric
X24: Maul | Y24: Martial Melee | Z24: 2d6 | AA24: Bludgeoning | AB24: Heavy, Two-Handed | AC24: STR | AD24: 10 | AF24: True Strike | AG24: 0 | AH24: Divination | AI24: 1 action | AJ24: 30 feet | AK24: S | AL24: Up to 1 round | AM24: Yes | AN24: No | AO24: Bard, Sorcerer, Warlock, Wizard
X25: Morningstar | Y25: Martial Melee | Z25: 1d8 | AA25: Piercing | AC25: STR | AD25: 4 | AF25: Vicious Mockery | AG25: 0 | AH25: Enchantment | AI25: 1 action | AJ25: 60 feet | AK25: V | AL25: Instantaneous | AM25: No | AN25: No | AO25: Bard
X26: Pike | Y26: Martial Melee | Z26: 1d10 | AA26: Piercing | AB26: Heavy, Reach, Two-Handed | AC26: STR | AD26: 18 | AF26: Alarm | AG26: 1 | AH26: Abjuration | AI26: 1 minute | AJ26: 30 feet | AK26: V, S, M | AL26: 8 hours | AM26: No | AN26: Yes | AO26: Ranger, Wizard
X27: Rapier | Y27: Martial Melee | Z27: 1d8 | AA27: Piercing | AB27: Finesse | AC27: FIN | AD27: 2 | AF27: Animal Friendship | AG27: 1 | AH27: Enchantment | AI27: 1 action | AJ27: 30 feet | AK27: V, S, M | AL27: 24 hours | AM27: No | AN27: No | AO27: Bard, Druid, Ranger
X28: Scimitar | Y28: Martial Melee | Z28: 1d6 | AA28: Slashing | AB28: Finesse, Light | AC28: FIN | AD28: 3 | AF28: Bane | AG28: 1 | AH28: Enchantment | AI28: 1 action | AJ28: 30 feet | AK28: V, S, M | AL28: Up to 1 minute | AM28: Yes | AN28: No | AO28: Bard, Cleric
X29: Shortsword | Y29: Martial Melee | Z29: 1d6 | AA29: Piercing | AB29: Finesse, Light | AC29: FIN | AD29: 2 | AF29: Bless | AG29: 1 | AH29: Enchantment | AI29: 1 action | AJ29: 30 feet | AK29: V, S, M | AL29: Up to 1 minute | AM29: Yes | AN29: No | AO29: Cleric, Paladin
X30: Trident | Y30: Martial Melee | Z30: 1d6 | AA30: Piercing | AB30: Thrown (20/60), Versatile (1d8) | AC30: STR | AD30: 4 | AF30: Burning Hands | AG30: 1 | AH30: Evocation | AI30: 1 action | AJ30: Self | AK30: V, S | AL30: Instantaneous | AM30: No | AN30: No | AO30: Sorcerer, Wizard
X31: War pick | Y31: Martial Melee | Z31: 1d8 | AA31: Piercing | AC31: STR | AD31: 2 | AF31: Charm Person | AG31: 1 | AH31: Enchantment | AI31: 1 action | AJ31: 30 feet | AK31: V, S | AL31: 1 hour | AM31: No | AN31: No | AO31: Bard, Druid, Sorcerer, Warlock, Wizard
X32: Warhammer | Y32: Martial Melee | Z32: 1d8 | AA32: Bludgeoning | AB32: Versatile (1d10) | AC32: STR | AD32: 2 | AF32: Color Spray | AG32: 1 | AH32: Illusion | AI32: 1 action | AJ32: Self | AK32: V, S, M | AL32: 1 round | AM32: No | AN32: No | AO32: Sorcerer, Wizard
X33: Whip | Y33: Martial Melee | Z33: 1d4 | AA33: Slashing | AB33: Finesse, Reach | AC33: FIN | AD33: 3 | AF33: Command | AG33: 1 | AH33: Enchantment | AI33: 1 action | AJ33: 60 feet | AK33: V | AL33: 1 round | AM33: No | AN33: No | AO33: Cleric, Paladin
X34: Blowgun | Y34: Martial Ranged | Z34: 1 | AA34: Piercing | AB34: Ammunition (25/100), Loading | AC34: DEX | AD34: 1 | AF34: Comprehend Languages | AG34: 1 | AH34: Divination | AI34: 1 action | AJ34: Self | AK34: V, S, M | AL34: 1 hour | AM34: No | AN34: Yes | AO34: Bard, Sorcerer, Warlock, Wizard
X35: Crossbow, hand | Y35: Martial Ranged | Z35: 1d6 | AA35: Piercing | AB35: Ammunition (30/120), Light, Loading | AC35: DEX | AD35: 3 | AF35: Create or Destroy Water | AG35: 1 | AH35: Transmutation | AI35: 1 action | AJ35: 30 feet | AK35: V, S, M | AL35: Instantaneous | AM35: No | AN35: No | AO35: Cleric, Druid
X36: Crossbow, heavy | Y36: Martial Ranged | Z36: 1d10 | AA36: Piercing | AB36: Ammunition (100/400), Heavy, Loading, Two-Handed | AC36: DEX | AD36: 18 | AF36: Cure Wounds | AG36: 1 | AH36: Evocation | AI36: 1 action | AJ36: Touch | AK36: V, S | AL36: Instantaneous | AM36: No | AN36: No | AO36: Bard, Cleric, Druid, Paladin, Ranger
X37: Longbow | Y37: Martial Ranged | Z37: 1d8 | AA37: Piercing | AB37: Ammunition (150/600), Heavy, Two-Handed | AC37: DEX | AD37: 2 | AF37: Detect Evil and Good | AG37: 1 | AH37: Divination | AI37: 1 action | AJ37: Self | AK37: V, S | AL37: Up to 10 minutes | AM37: Yes | AN37: No | AO37: Cleric, Paladin
X38: Net | Y38: Martial Ranged | AB38: Thrown (5/15), Special | AC38: DEX | AD38: 3 | AF38: Detect Magic | AG38: 1 | AH38: Divination | AI38: 1 action | AJ38: Self | AK38: V, S | AL38: Up to 10 minutes | AM38: Yes | AN38: Yes | AO38: Bard, Cleric, Druid, Paladin, Ranger, Sorcerer, Wizard
AF39: Detect Poison and Disease | AG39: 1 | AH39: Divination | AI39: 1 action | AJ39: Self | AK39: V, S, M | AL39: Up to 10 minutes | AM39: Yes | AN39: Yes | AO39: Cleric, Druid, Paladin, Ranger
AF40: Disguise Self | AG40: 1 | AH40: Illusion | AI40: 1 action | AJ40: Self | AK40: V, S | AL40: 1 hour | AM40: No | AN40: No | AO40: Bard, Sorcerer, Wizard
...
